--------------------------------------------------------------------------
gaierror                                  Traceback (most recent call last)
~/anaconda3/lib/python3.8/site-packages/urllib3/connection.py in _new_conn(self)
    158         try:
--> 159             conn = connection.create_connection(
    160                 (self._dns_host, self.port), self.timeout, **extra_kw

~/anaconda3/lib/python3.8/site-packages/urllib3/util/connection.py in create_connection(address, timeout, source_address, socket_options)
     60
---> 61     for res in socket.getaddrinfo(host, port, family, socket.SOCK_STREAM):
     62         af, socktype, proto, canonname, sa = res

~/anaconda3/lib/python3.8/socket.py in getaddrinfo(host, port, family, type, proto, flags)
    917     addrlist = []
--> 918     for res in _socket.getaddrinfo(host, port, family, type, proto, flags):
    919         af, socktype, proto, canonname, sa = res

gaierror: [Errno -3] Temporary failure in name resolution

During handling of the above exception, another exception occurred:

NewConnectionError                        Traceback (most recent call last)
~/anaconda3/lib/python3.8/site-packages/urllib3/connectionpool.py in urlopen(self, method, url, body, headers, retries, redirect, assert_same_host, timeout, pool_timeout, release_conn, chunked, body_pos, **response_kw)
    669             # Make the request on the httplib connection object.
--> 670             httplib_response = self._make_request(
    671                 conn,

~/anaconda3/lib/python3.8/site-packages/urllib3/connectionpool.py in _make_request(self, conn, method, url, timeout, chunked, **httplib_request_kw)
    380         try:
--> 381             self._validate_conn(conn)
    382         except (SocketTimeout, BaseSSLError) as e:

~/anaconda3/lib/python3.8/site-packages/urllib3/connectionpool.py in _validate_conn(self, conn)
    975         if not getattr(conn, "sock", None):  # AppEngine might not have  `.sock`
--> 976             conn.connect()
    977

~/anaconda3/lib/python3.8/site-packages/urllib3/connection.py in connect(self)
    307         # Add certificate verification
--> 308         conn = self._new_conn()
    309         hostname = self.host

~/anaconda3/lib/python3.8/site-packages/urllib3/connection.py in _new_conn(self)
    170         except SocketError as e:
--> 171             raise NewConnectionError(
    172                 self, "Failed to establish a new connection: %s" % e

NewConnectionError: <urllib3.connection.HTTPSConnection object at 0x7f12f2665070>: Failed to establish a new connection: [Errno -3] Temporary failure in name resolution

During handling of the above exception, another exception occurred:

MaxRetryError                             Traceback (most recent call last)
~/anaconda3/lib/python3.8/site-packages/requests/adapters.py in send(self, request, stream, timeout, verify, cert, proxies)
    438             if not chunked:
--> 439                 resp = conn.urlopen(
    440                     method=request.method,

~/anaconda3/lib/python3.8/site-packages/urllib3/connectionpool.py in urlopen(self, method, url, body, headers, retries, redirect, assert_same_host, timeout, pool_timeout, release_conn, chunked, body_pos, **response_kw)
    723
--> 724             retries = retries.increment(
    725                 method, url, error=e, _pool=self, _stacktrace=sys.exc_info()[2]

~/anaconda3/lib/python3.8/site-packages/urllib3/util/retry.py in increment(self, method, url, response, error, _pool, _stacktrace)
    438         if new_retry.is_exhausted():
--> 439             raise MaxRetryError(_pool, url, error or ResponseError(cause))
    440

MaxRetryError: HTTPSConnectionPool(host='api.darksky.net', port=443): Max retries exceeded with url: /forecast/723a6f9dbda64ae1e0b9fdde14ba752e/31.36868194,-102.0423217,1578614400?exclude=currently,flags&units=si (Caused by NewConnectionError('<urllib3.connection.HTTPSConnection object at 0x7f12f2665070>: Failed to establish a new connection: [Errno -3] Temporary failure in name resolution'))

During handling of the above exception, another exception occurred:

ConnectionError                           Traceback (most recent call last)
<ipython-input-25-afe0c0b227f6> in <module>
     39
     40             # Getting the API call
---> 41             response = requests.get(url)
     42             counter = counter + 1
     43             print(counter)

~/anaconda3/lib/python3.8/site-packages/requests/api.py in get(url, params, **kwargs)
     74
     75     kwargs.setdefault('allow_redirects', True)
---> 76     return request('get', url, params=params, **kwargs)
     77
     78

~/anaconda3/lib/python3.8/site-packages/requests/api.py in request(method, url, **kwargs)
     59     # cases, and look like a memory leak in others.
     60     with sessions.Session() as session:
---> 61         return session.request(method=method, url=url, **kwargs)
     62
     63

~/anaconda3/lib/python3.8/site-packages/requests/sessions.py in request(self, method, url, params, data, headers, cookies, files, auth, timeout, allow_redirects, proxies, hooks, stream, verify, cert, json)
    528         }
    529         send_kwargs.update(settings)
--> 530         resp = self.send(prep, **send_kwargs)
    531
    532         return resp

~/anaconda3/lib/python3.8/site-packages/requests/sessions.py in send(self, request, **kwargs)
    641
    642         # Send the request
--> 643         r = adapter.send(request, **kwargs)
    644
    645         # Total elapsed time of the request (approximately)

~/anaconda3/lib/python3.8/site-packages/requests/adapters.py in send(self, request, stream, timeout, verify, cert, proxies)
    514                 raise SSLError(e, request=request)
    515
--> 516             raise ConnectionError(e, request=request)
    517
    518         except ClosedPoolError as e:

ConnectionError: HTTPSConnectionPool(host='api.darksky.net', port=443): Max retries exceeded with url: /forecast/723a6f9dbda64ae1e0b9fdde14ba752e/31.36868194,-102.0423217,1578614400?exclude=currently,flags&units=si (Caused by NewConnectionError('<urllib3.connection.HTTPSConnection object at 0x7f12f2665070>: Failed to establish a new connection: [Errno -3] Temporary failure in name resolution'))
